Workbook

Sheet Todas as Turmas
A1: OLIMPÍADA BRASILEIRA DE LÍNGUA INGLESA (OBLI 2024.2 - SELETA) • COOEDUCAR CARLOS CHAGAS
A2: Q01 a Q20: READING (Compreensão Leitora - 20 pts) | Q21 a Q30: LISTENING (Compreensão Auditiva - 10 pts) | Total: 30 pts
A4: TURMA: 6º ANO (12 alunos)
A5: Nº | B5: Nome do Aluno | C5: Q01 | D5: Q02 | E5: Q03 | F5: Q04 | G5: Q05 | H5: Q06 | I5: Q07 | J5: Q08 | K5: Q09 | L5: Q10 | M5: Q11 | N5: Q12 | O5: Q13 | P5: Q14 | Q5: Q15 | R5: Q16 | S5: Q17 | T5: Q18 | U5: Q19 | V5: Q20 | W5: Q21 | X5: Q22 | Y5: Q23 | Z5: Q24 | AA5: Q25 | AB5: Q26 | AC5: Q27 | AD5: Q28 | AE5: Q29 | AF5: Q30 | AG5: Total (30) | AH5: % Geral | AI5: Reading (20) | AJ5: % Reading | AK5: Listening (10) | AL5: % Listening
A6: ★ | B6: [ GABARITO OFICIAL — 6º ANO ] | C6: E | D6: B | E6: A | F6: E | G6: E | H6: D | I6: A | J6: D | K6: D | L6: C | M6: C | N6: E | O6: B | P6: E | Q6: E | R6: E | S6: E | T6: C | U6: B | V6: D | W6: A | X6: B | Y6: D | Z6: B | AA6: A | AB6: E | AC6: A | AD6: E | AE6: C | AF6: E | AG6: =COUNTA(C6:AF6) | AH6: Gabarito | AI6: =COUNTA(C6:V6) | AJ6: Reading | AK6: =COUNTA(W6:AF6) | AL6: Listening
A7: 1 | B7: Aisha Santos David | C7: B | D7: A | E7: D | F7: D | G7: B | H7: B | I7: D | J7: A | K7: D | L7: E | M7: C | N7: C | O7: A | P7: E | Q7: D | R7: A | S7: D | T7: C | U7: B | V7: A | W7: C | X7: B | Y7: C | Z7: B | AA7: A | AB7: C | AC7: D | AD7: E | AE7: D | AF7: B | AG7: =SUMPRODUCT((C7:AF7<>"")*((C7:AF7=$C$6:$AF$6)+($C$6:$AF$6="*")>0)*($C$6:$AF$6<>"")) | AH7: =IF(COUNTA($C$6:$AF$6)>0, AG7/COUNTA($C$6:$AF$6), 0) | AI7: =SUMPRODUCT((C7:V7<>"")*((C7:V7=$C$6:$V$6)+($C$6:$V$6="*")>0)*($C$6:$V$6<>"")) | AJ7: =IF(COUNTA($C$6:$V$6)>0, AI7/COUNTA($C$6:$V$6), 0) | AK7: =SUMPRODUCT((W7:AF7<>"")*((W7:AF7=$W$6:$AF$6)+($W$6:$AF$6="*")>0)*($W$6:$AF$6<>"")) | AL7: =IF(COUNTA($W$6:$AF$6)>0, AK7/COUNTA($W$6:$AF$6), 0)
A8: 2 | B8: Ana Júlia Bomfim Coutinho | C8: E | D8: C | E8: E | F8: E | G8: E | H8: D | I8: E | J8: D | K8: D | L8: C | M8: C | N8: E | O8: D | P8: E | Q8: D | R8: B | S8: C | T8: B | U8: B | V8: C | W8: B | X8: B | Y8: C | Z8: D | AA8: A | AB8: C | AC8: C | AD8: B | AE8: C | AF8: E | AG8: =SUMPRODUCT((C8:AF8<>"")*((C8:AF8=$C$6:$AF$6)+($C$6:$AF$6="*")>0)*($C$6:$AF$6<>"")) | AH8: =IF(COUNTA($C$6:$AF$6)>0, AG8/COUNTA($C$6:$AF$6), 0) | AI8: =SUMPRODUCT((C8:V8<>"")*((C8:V8=$C$6:$V$6)+($C$6:$V$6="*")>0)*($C$6:$V$6<>"")) | AJ8: =IF(COUNTA($C$6:$V$6)>0, AI8/COUNTA($C$6:$V$6), 0) | AK8: =SUMPRODUCT((W8:AF8<>"")*((W8:AF8=$W$6:$AF$6)+($W$6:$AF$6="*")>0)*($W$6:$AF$6<>"")) | AL8: =IF(COUNTA($W$6:$AF$6)>0, AK8/COUNTA($W$6:$AF$6), 0)
A9: 3 | B9: Arthur Vieira Trindade | C9: B | D9: A | E9: A | F9: A | G9: A | H9: B | I9: E | J9: B | K9: D | L9: C | M9: A | N9: A | O9: A | P9: A | Q9: C | R9: C | S9: D | T9: C | U9: A | V9: A | W9: A | X9: B | Y9: B | Z9: B | AA9: A | AB9: B | AC9: B | AD9: C | AE9: C | AF9: E | AG9: =SUMPRODUCT((C9:AF9<>"")*((C9:AF9=$C$6:$AF$6)+($C$6:$AF$6="*")>0)*($C$6:$AF$6<>"")) | AH9: =IF(COUNTA($C$6:$AF$6)>0, AG9/COUNTA($C$6:$AF$6), 0) | AI9: =SUMPRODUCT((C9:V9<>"")*((C9:V9=$C$6:$V$6)+($C$6:$V$6="*")>0)*($C$6:$V$6<>"")) | AJ9: =IF(COUNTA($C$6:$V$6)>0, AI9/COUNTA($C$6:$V$6), 0) | AK9: =SUMPRODUCT((W9:AF9<>"")*((W9:AF9=$W$6:$AF$6)+($W$6:$AF$6="*")>0)*($W$6:$AF$6<>"")) | AL9: =IF(COUNTA($W$6:$AF$6)>0, AK9/COUNTA($W$6:$AF$6), 0)
A10: 4 | B10: Benício Paim De Souza Jardim | C10: A | D10: A | E10: A | F10: E | G10: E | H10: D | I10: E | J10: D | K10: C | L10: C | M10: C | N10: B | O10: B | P10: E | Q10: E | R10: E | S10: B | T10: C | U10: C | V10: A | W10: D | X10: B | Y10: C | Z10: B | AA10: A | AB10: A | AC10: C | AD10: E | AE10: C | AF10: E | AG10: =SUMPRODUCT((C10:AF10<>"")*((C10:AF10=$C$6:$AF$6)+($C$6:$AF$6="*")>0)*($C$6:$AF$6<>"")) | AH10: =IF(COUNTA($C$6:$AF$6)>0, AG10/COUNTA($C$6:$AF$6), 0) | AI10: =SUMPRODUCT((C10:V10<>"")*((C10:V10=$C$6:$V$6)+($C$6:$V$6="*")>0)*($C$6:$V$6<>"")) | AJ10: =IF(COUNTA($C$6:$V$6)>0, AI10/COUNTA($C$6:$V$6), 0) | AK10: =SUMPRODUCT((W10:AF10<>"")*((W10:AF10=$W$6:$AF$6)+($W$6:$AF$6="*")>0)*($W$6:$AF$6<>"")) | AL10: =IF(COUNTA($W$6:$AF$6)>0, AK10/COUNTA($W$6:$AF$6), 0)
A11: 6 | B11: Daniel Dias Souto | C11: E | D11: A | E11: A | F11: A | G11: A | H11: A | I11: E | J11: A | K11: A | L11: E | M11: C | N11: E | O11: B | P11: E | Q11: D | R11: B | S11: A | T11: A | U11: B | V11: B | W11: D | X11: B | Y11: D | Z11: D | AA11: A | AB11: E | AC11: A | AD11: B | AE11: C | AF11: E | AG11: =SUMPRODUCT((C11:AF11<>"")*((C11:AF11=$C$6:$AF$6)+($C$6:$AF$6="*")>0)*($C$6:$AF$6<>"")) | AH11: =IF(COUNTA($C$6:$AF$6)>0, AG11/COUNTA($C$6:$AF$6), 0) | AI11: =SUMPRODUCT((C11:V11<>"")*((C11:V11=$C$6:$V$6)+($C$6:$V$6="*")>0)*($C$6:$V$6<>"")) | AJ11: =IF(COUNTA($C$6:$V$6)>0, AI11/COUNTA($C$6:$V$6), 0) | AK11: =SUMPRODUCT((W11:AF11<>"")*((W11:AF11=$W$6:$AF$6)+($W$6:$AF$6="*")>0)*($W$6:$AF$6<>"")) | AL11: =IF(COUNTA($W$6:$AF$6)>0, AK11/COUNTA($W$6:$AF$6), 0)
A12: 7 | B12: Davi Laender Norte Brito | C12: E | D12: C | E12: A | F12: B | G12: A | H12: D | I12: E | J12: D | K12: B | L12: C | M12: C | N12: C | O12: B | P12: E | Q12: E | R12: A | S12: B | T12: D | U12: D | V12: C | W12: D | X12: B | Y12: D | Z12: D | AA12: A | AB12: E | AC12: D | AD12: E | AE12: C | AF12: C | AG12: =SUMPRODUCT((C12:AF12<>"")*((C12:AF12=$C$6:$AF$6)+($C$6:$AF$6="*")>0)*($C$6:$AF$6<>"")) | AH12: =IF(COUNTA($C$6:$AF$6)>0, AG12/COUNTA($C$6:$AF$6), 0) | AI12: =SUMPRODUCT((C12:V12<>"")*((C12:V12=$C$6:$V$6)+($C$6:$V$6="*")>0)*($C$6:$V$6<>"")) | AJ12: =IF(COUNTA($C$6:$V$6)>0, AI12/COUNTA($C$6:$V$6), 0) | AK12: =SUMPRODUCT((W12:AF12<>"")*((W12:AF12=$W$6:$AF$6)+($W$6:$AF$6="*")>0)*($W$6:$AF$6<>"")) | AL12: =IF(COUNTA($W$6:$AF$6)>0, AK12/COUNTA($W$6:$AF$6), 0)
A13: 8 | B13: Davi Rocha Aguiar | C13: B | D13: D | E13: A | G13: C | H13: B | I13: A | J13: A | K13: B | L13: D | M13: D | N13: B | O13: D | P13: B | Q13: E | R13: A | S13: B | T13: C | U13: B | V13: D | W13: C | X13: D | Y13: D | Z13: E | AA13: E | AB13: C | AC13: D | AD13: C | AE13: D | AF13: C | AG13: =SUMPRODUCT((C13:AF13<>"")*((C13:AF13=$C$6:$AF$6)+($C$6:$AF$6="*")>0)*($C$6:$AF$6<>"")) | AH13: =IF(COUNTA($C$6:$AF$6)>0, AG13/COUNTA($C$6:$AF$6), 0) | AI13: =SUMPRODUCT((C13:V13<>"")*((C13:V13=$C$6:$V$6)+($C$6:$V$6="*")>0)*($C$6:$V$6<>"")) | AJ13: =IF(COUNTA($C$6:$V$6)>0, AI13/COUNTA($C$6:$V$6), 0) | AK13: =SUMPRODUCT((W13:AF13<>"")*((W13:AF13=$W$6:$AF$6)+($W$6:$AF$6="*")>0)*($W$6:$AF$6<>"")) | AL13: =IF(COUNTA($W$6:$AF$6)>0, AK13/COUNTA($W$6:$AF$6), 0)
A14: 9 | B14: Dely Cotrim Batista Coelho | AG14: =SUMPRODUCT((C14:AF14<>"")*((C14:AF14=$C$6:$AF$6)+($C$6:$AF$6="*")>0)*($C$6:$AF$6<>"")) | AH14: =IF(COUNTA($C$6:$AF$6)>0, AG14/COUNTA($C$6:$AF$6), 0) | AI14: =SUMPRODUCT((C14:V14<>"")*((C14:V14=$C$6:$V$6)+($C$6:$V$6="*")>0)*($C$6:$V$6<>"")) | AJ14: =IF(COUNTA($C$6:$V$6)>0, AI14/COUNTA($C$6:$V$6), 0) | AK14: =SUMPRODUCT((W14:AF14<>"")*((W14:AF14=$W$6:$AF$6)+($W$6:$AF$6="*")>0)*($W$6:$AF$6<>"")) | AL14: =IF(COUNTA($W$6:$AF$6)>0, AK14/COUNTA($W$6:$AF$6), 0)
A15: 10 | B15: Laura Andrade Coelho Dos Santos | C15: B | D15: A | E15: E | F15: A | G15: A | H15: B | I15: E | J15: D | K15: E | L15: B | M15: A | N15: C | O15: B | P15: E | Q15: A | R15: A | S15: D | T15: B | U15: B | V15: D | W15: C | X15: B | Y15: E | Z15: D | AA15: D | AB15: C | AC15: A | AD15: D | AE15: C | AF15: A | AG15: =SUMPRODUCT((C15:AF15<>"")*((C15:AF15=$C$6:$AF$6)+($C$6:$AF$6="*")>0)*($C$6:$AF$6<>"")) | AH15: =IF(COUNTA($C$6:$AF$6)>0, AG15/COUNTA($C$6:$AF$6), 0) | AI15: =SUMPRODUCT((C15:V15<>"")*((C15:V15=$C$6:$V$6)+($C$6:$V$6="*")>0)*($C$6:$V$6<>"")) | AJ15: =IF(COUNTA($C$6:$V$6)>0, AI15/COUNTA($C$6:$V$6), 0) | AK15: =SUMPRODUCT((W15:AF15<>"")*((W15:AF15=$W$6:$AF$6)+($W$6:$AF$6="*")>0)*($W$6:$AF$6<>"")) | AL15: =IF(COUNTA($W$6:$AF$6)>0, AK15/COUNTA($W$6:$AF$6), 0)
A16: 11 | B16: Laura Gomes Prates | C16: E | D16: D | E16: E | F16: C | G16: E | H16: B | I16: C | J16: B | K16: E | L16: B | M16: D | N16: C | O16: A | P16: D | Q16: A | R16: D | S16: B | T16: A | U16: B | V16: B | W16: C | X16: A | Y16: B | Z16: B | AA16: E | AB16: C | AC16: D | AD16: B | AE16: C | AF16: D | AG16: =SUMPRODUCT((C16:AF16<>"")*((C16:AF16=$C$6:$AF$6)+($C$6:$AF$6="*")>0)*($C$6:$AF$6<>"")) | AH16: =IF(COUNTA($C$6:$AF$6)>0, AG16/COUNTA($C$6:$AF$6), 0) | AI16: =SUMPRODUCT((C16:V16<>"")*((C16:V16=$C$6:$V$6)+($C$6:$V$6="*")>0)*($C$6:$V$6<>"")) | AJ16: =IF(COUNTA($C$6:$V$6)>0, AI16/COUNTA($C$6:$V$6), 0) | AK16: =SUMPRODUCT((W16:AF16<>"")*((W16:AF16=$W$6:$AF$6)+($W$6:$AF$6="*")>0)*($W$6:$AF$6<>"")) | AL16: =IF(COUNTA($W$6:$AF$6)>0, AK16/COUNTA($W$6:$AF$6), 0)
A17: 12 | B17: Maria Clara Almeida Coutinho | C17: E | D17: D | E17: D | F17: A | G17: E | H17: A | I17: E | J17: B | K17: A | L17: E | M17: D | N17: E | O17: B | P17: E | Q17: B | R17: C | S17: B | T17: B | U17: C | V17: C | W17: C | X17: B | Y17: B | Z17: B | AA17: E | AB17: B | AC17: B | AD17: E | AE17: C | AF17: B | AG17: =SUMPRODUCT((C17:AF17<>"")*((C17:AF17=$C$6:$AF$6)+($C$6:$AF$6="*")>0)*($C$6:$AF$6<>"")) | AH17: =IF(COUNTA($C$6:$AF$6)>0, AG17/COUNTA($C$6:$AF$6), 0) | AI17: =SUMPRODUCT((C17:V17<>"")*((C17:V17=$C$6:$V$6)+($C$6:$V$6="*")>0)*($C$6:$V$6<>"")) | AJ17: =IF(COUNTA($C$6:$V$6)>0, AI17/COUNTA($C$6:$V$6), 0) | AK17: =SUMPRODUCT((W17:AF17<>"")*((W17:AF17=$W$6:$AF$6)+($W$6:$AF$6="*")>0)*($W$6:$AF$6<>"")) | AL17: =IF(COUNTA($W$6:$AF$6)>0, AK17/COUNTA($W$6:$AF$6), 0)
A18: 13 | B18: Valentina Silva Soares | C18: B | D18: D | E18: E | F18: A | G18: C | H18: C | I18: A | J18: A | K18: B | L18: E | M18: D | N18: B | O18: A | P18: C | Q18: D | R18: D | S18: B | T18: B | U18: D | V18: B | W18: D | X18: B | Y18: B | Z18: D | AA18: A | AB18: A | AC18: A | AD18: B | AE18: B | AF18: A | AG18: =SUMPRODUCT((C18:AF18<>"")*((C18:AF18=$C$6:$AF$6)+($C$6:$AF$6="*")>0)*($C$6:$AF$6<>"")) | AH18: =IF(COUNTA($C$6:$AF$6)>0, AG18/COUNTA($C$6:$AF$6), 0) | AI18: =SUMPRODUCT((C18:V18<>"")*((C18:V18=$C$6:$V$6)+($C$6:$V$6="*")>0)*($C$6:$V$6<>"")) | AJ18: =IF(COUNTA($C$6:$V$6)>0, AI18/COUNTA($C$6:$V$6), 0) | AK18: =SUMPRODUCT((W18:AF18<>"")*((W18:AF18=$W$6:$AF$6)+($W$6:$AF$6="*")>0)*($W$6:$AF$6<>"")) | AL18: =IF(COUNTA($W$6:$AF$6)>0, AK18/COUNTA($W$6:$AF$6), 0)
A20: TURMA: 7º ANO (20 alunos)
A21: Nº | B21: Nome do Aluno | C21: Q01 | D21: Q02 | E21: Q03 | F21: Q04 | G21: Q05 | H21: Q06 | I21: Q07 | J21: Q08 | K21: Q09 | L21: Q10 | M21: Q11 | N21: Q12 | O21: Q13 | P21: Q14 | Q21: Q15 | R21: Q16 | S21: Q17 | T21: Q18 | U21: Q19 | V21: Q20 | W21: Q21 | X21: Q22 | Y21: Q23 | Z21: Q24 | AA21: Q25 | AB21: Q26 | AC21: Q27 | AD21: Q28 | AE21: Q29 | AF21: Q30 | AG21: Total (30) | AH21: % Geral | AI21: Reading (20) | AJ21: % Reading | AK21: Listening (10) | AL21: % Listening
A22: ★ | B22: [ GABARITO OFICIAL — 7º ANO ] | C22: E | D22: B | E22: A | F22: E | G22: E | H22: D | I22: A | J22: D | K22: D | L22: C | M22: C | N22: E | O22: B | P22: E | Q22: E | R22: E | S22: E | T22: C | U22: B | V22: D | W22: A | X22: B | Y22: D | Z22: B | AA22: A | AB22: E | AC22: A | AD22: E | AE22: C | AF22: E | AG22: =COUNTA(C22:AF22) | AH22: Gabarito | AI22: =COUNTA(C22:V22) | AJ22: Reading | AK22: =COUNTA(W22:AF22) | AL22: Listening
A23: 1 | B23: Alice De Souza Bossi Lima | C23: A | D23: C | E23: A | F23: E | G23: C | H23: D | I23: A | J23: D | K23: B | L23: C | M23: C | N23: E | O23: B | P23: E | Q23: E | R23: E | S23: E | T23: C | U23: B | V23: D | W23: C | X23: B | Y23: D | Z23: D | AA23: A | AB23: E | AC23: C | AD23: E | AE23: C | AF23: E | AG23: =SUMPRODUCT((C23:AF23<>"")*((C23:AF23=$C$22:$AF$22)+($C$22:$AF$22="*")>0)*($C$22:$AF$22<>"")) | AH23: =IF(COUNTA($C$22:$AF$22)>0, AG23/COUNTA($C$22:$AF$22), 0) | AI23: =SUMPRODUCT((C23:V23<>"")*((C23:V23=$C$22:$V$22)+($C$22:$V$22="*")>0)*($C$22:$V$22<>"")) | AJ23: =IF(COUNTA($C$22:$V$22)>0, AI23/COUNTA($C$22:$V$22), 0) | AK23: =SUMPRODUCT((W23:AF23<>"")*((W23:AF23=$W$22:$AF$22)+($W$22:$AF$22="*")>0)*($W$22:$AF$22<>"")) | AL23: =IF(COUNTA($W$22:$AF$22)>0, AK23/COUNTA($W$22:$AF$22), 0)
A24: 2 | B24: Cauã Jimenez Figueiredo Costa | C24: A | D24: D | E24: A | F24: E | G24: E | H24: D | I24: D | J24: A | K24: E | L24: C | M24: C | N24: E | O24: B | P24: E | Q24: A | R24: C | S24: A | T24: A | U24: A | V24: E | W24: D | X24: B | Y24: D | Z24: B | AA24: A | AB24: A | AC24: B | AD24: E | AE24: C | AF24: C | AG24: =SUMPRODUCT((C24:AF24<>"")*((C24:AF24=$C$22:$AF$22)+($C$22:$AF$22="*")>0)*($C$22:$AF$22<>"")) | AH24: =IF(COUNTA($C$22:$AF$22)>0, AG24/COUNTA($C$22:$AF$22), 0) | AI24: =SUMPRODUCT((C24:V24<>"")*((C24:V24=$C$22:$V$22)+($C$22:$V$22="*")>0)*($C$22:$V$22<>"")) | AJ24: =IF(COUNTA($C$22:$V$22)>0, AI24/COUNTA($C$22:$V$22), 0) | AK24: =SUMPRODUCT((W24:AF24<>"")*((W24:AF24=$W$22:$AF$22)+($W$22:$AF$22="*")>0)*($W$22:$AF$22<>"")) | AL24: =IF(COUNTA($W$22:$AF$22)>0, AK24/COUNTA($W$22:$AF$22), 0)
A25: 3 | B25: Isabela Lima Barbosa | C25: C | D25: D | E25: A | F25: E | G25: A | H25: D | I25: E | J25: B | K25: A | L25: E | M25: D | N25: B | O25: B | P25: A | Q25: B | R25: A | S25: B | T25: B | U25: B | V25: D | W25: C | X25: B | Y25: D | Z25: B | AA25: A | AB25: E | AC25: B | AD25: E | AE25: C | AF25: C | AG25: =SUMPRODUCT((C25:AF25<>"")*((C25:AF25=$C$22:$AF$22)+($C$22:$AF$22="*")>0)*($C$22:$AF$22<>"")) | AH25: =IF(COUNTA($C$22:$AF$22)>0, AG25/COUNTA($C$22:$AF$22), 0) | AI25: =SUMPRODUCT((C25:V25<>"")*((C25:V25=$C$22:$V$22)+($C$22:$V$22="*")>0)*($C$22:$V$22<>"")) | AJ25: =IF(COUNTA($C$22:$V$22)>0, AI25/COUNTA($C$22:$V$22), 0) | AK25: =SUMPRODUCT((W25:AF25<>"")*((W25:AF25=$W$22:$AF$22)+($W$22:$AF$22="*")>0)*($W$22:$AF$22<>"")) | AL25: =IF(COUNTA($W$22:$AF$22)>0, AK25/COUNTA($W$22:$AF$22), 0)
A26: 4 | B26: Isadora Amaral Santos | AG26: =SUMPRODUCT((C26:AF26<>"")*((C26:AF26=$C$22:$AF$22)+($C$22:$AF$22="*")>0)*($C$22:$AF$22<>"")) | AH26: =IF(COUNTA($C$22:$AF$22)>0, AG26/COUNTA($C$22:$AF$22), 0) | AI26: =SUMPRODUCT((C26:V26<>"")*((C26:V26=$C$22:$V$22)+($C$22:$V$22="*")>0)*($C$22:$V$22<>"")) | AJ26: =IF(COUNTA($C$22:$V$22)>0, AI26/COUNTA($C$22:$V$22), 0) | AK26: =SUMPRODUCT((W26:AF26<>"")*((W26:AF26=$W$22:$AF$22)+($W$22:$AF$22="*")>0)*($W$22:$AF$22<>"")) | AL26: =IF(COUNTA($W$22:$AF$22)>0, AK26/COUNTA($W$22:$AF$22), 0)
A27: 5 | B27: Isis Costa Rodrigues De Oliveira | C27: B | D27: A | E27: E | F27: E | G27: C | H27: A | I27: B | J27: B | K27: A | L27: E | M27: D | N27: B | O27: D | P27: B | Q27: C | R27: A | S27: E | T27: D | U27: B | V27: B | W27: B | X27: B | Y27: C | Z27: A | AA27: D | AB27: B | AC27: D | AD27: B | AE27: C | AF27: B | AG27: =SUMPRODUCT((C27:AF27<>"")*((C27:AF27=$C$22:$AF$22)+($C$22:$AF$22="*")>0)*($C$22:$AF$22<>"")) | AH27: =IF(COUNTA($C$22:$AF$22)>0, AG27/COUNTA($C$22:$AF$22), 0) | AI27: =SUMPRODUCT((C27:V27<>"")*((C27:V27=$C$22:$V$22)+($C$22:$V$22="*")>0)*($C$22:$V$22<>"")) | AJ27: =IF(COUNTA($C$22:$V$22)>0, AI27/COUNTA($C$22:$V$22), 0) | AK27: =SUMPRODUCT((W27:AF27<>"")*((W27:AF27=$W$22:$AF$22)+($W$22:$AF$22="*")>0)*($W$22:$AF$22<>"")) | AL27: =IF(COUNTA($W$22:$AF$22)>0, AK27/COUNTA($W$22:$AF$22), 0)
A28: 6 | B28: Isly De Souza Jardim Ferreira | C28: A | D28: E | E28: A | F28: E | G28: C | H28: B | I28: E | J28: A | K28: B | L28: C | M28: E | N28: E | O28: E | P28: E | Q28: C | R28: C | S28: D | T28: B | U28: B | V28: B | W28: A | X28: B | Y28: B | Z28: E | AA28: B | AB28: B | AC28: D | AD28: C | AE28: E | AF28: E | AG28: =SUMPRODUCT((C28:AF28<>"")*((C28:AF28=$C$22:$AF$22)+($C$22:$AF$22="*")>0)*($C$22:$AF$22<>"")) | AH28: =IF(COUNTA($C$22:$AF$22)>0, AG28/COUNTA($C$22:$AF$22), 0) | AI28: =SUMPRODUCT((C28:V28<>"")*((C28:V28=$C$22:$V$22)+($C$22:$V$22="*")>0)*($C$22:$V$22<>"")) | AJ28: =IF(COUNTA($C$22:$V$22)>0, AI28/COUNTA($C$22:$V$22), 0) | AK28: =SUMPRODUCT((W28:AF28<>"")*((W28:AF28=$W$22:$AF$22)+($W$22:$AF$22="*")>0)*($W$22:$AF$22<>"")) | AL28: =IF(COUNTA($W$22:$AF$22)>0, AK28/COUNTA($W$22:$AF$22), 0)
A29: 7 | B29: Iuri Emanuel Lisboa Coutinho | C29: E | D29: A | E29: E | F29: E | G29: E | H29: D | I29: A | J29: D | K29: B | L29: C | M29: C | N29: E | O29: B | P29: E | Q29: E | R29: E | S29: E | T29: C | U29: D | V29: D | W29: C | X29: B | Y29: D | Z29: B | AA29: A | AB29: D | AC29: A | AD29: E | AE29: C | AF29: E | AG29: =SUMPRODUCT((C29:AF29<>"")*((C29:AF29=$C$22:$AF$22)+($C$22:$AF$22="*")>0)*($C$22:$AF$22<>"")) | AH29: =IF(COUNTA($C$22:$AF$22)>0, AG29/COUNTA($C$22:$AF$22), 0) | AI29: =SUMPRODUCT((C29:V29<>"")*((C29:V29=$C$22:$V$22)+($C$22:$V$22="*")>0)*($C$22:$V$22<>"")) | AJ29: =IF(COUNTA($C$22:$V$22)>0, AI29/COUNTA($C$22:$V$22), 0) | AK29: =SUMPRODUCT((W29:AF29<>"")*((W29:AF29=$W$22:$AF$22)+($W$22:$AF$22="*")>0)*($W$22:$AF$22<>"")) | AL29: =IF(COUNTA($W$22:$AF$22)>0, AK29/COUNTA($W$22:$AF$22), 0)
A30: 8 | B30: Júlia Aguilar Vieira De Sousa Lima | C30: B | D30: B | E30: E | F30: D | G30: A | H30: A | I30: E | J30: B | K30: D | L30: E | M30: D | N30: E | O30: B | P30: E | Q30: A | R30: C | S30: B | T30: B | U30: D | V30: D | W30: A | X30: B | Y30: D | Z30: B | AA30: A | AB30: E | AC30: D | AD30: C | AE30: C | AF30: A | AG30: =SUMPRODUCT((C30:AF30<>"")*((C30:AF30=$C$22:$AF$22)+($C$22:$AF$22="*")>0)*($C$22:$AF$22<>"")) | AH30: =IF(COUNTA($C$22:$AF$22)>0, AG30/COUNTA($C$22:$AF$22), 0) | AI30: =SUMPRODUCT((C30:V30<>"")*((C30:V30=$C$22:$V$22)+($C$22:$V$22="*")>0)*($C$22:$V$22<>"")) | AJ30: =IF(COUNTA($C$22:$V$22)>0, AI30/COUNTA($C$22:$V$22), 0) | AK30: =SUMPRODUCT((W30:AF30<>"")*((W30:AF30=$W$22:$AF$22)+($W$22:$AF$22="*")>0)*($W$22:$AF$22<>"")) | AL30: =IF(COUNTA($W$22:$AF$22)>0, AK30/COUNTA($W$22:$AF$22), 0)
A31: 9 | B31: Kauay Francisco Almeida Honorato | C31: C | D31: A | E31: D | F31: A | G31: E | H31: C | I31: A | J31: D | K31: A | L31: B | M31: A | N31: B | O31: A | P31: E | Q31: C | R31: A | S31: B | T31: A | U31: D | V31: E | W31: C | X31: C | Y31: B | Z31: D | AA31: A | AB31: D | AC31: D | AD31: E | AE31: C | AF31: C | AG31: =SUMPRODUCT((C31:AF31<>"")*((C31:AF31=$C$22:$AF$22)+($C$22:$AF$22="*")>0)*($C$22:$AF$22<>"")) | AH31: =IF(COUNTA($C$22:$AF$22)>0, AG31/COUNTA($C$22:$AF$22), 0) | AI31: =SUMPRODUCT((C31:V31<>"")*((C31:V31=$C$22:$V$22)+($C$22:$V$22="*")>0)*($C$22:$V$22<>"")) | AJ31: =IF(COUNTA($C$22:$V$22)>0, AI31/COUNTA($C$22:$V$22), 0) | AK31: =SUMPRODUCT((W31:AF31<>"")*((W31:AF31=$W$22:$AF$22)+($W$22:$AF$22="*")>0)*($W$22:$AF$22<>"")) | AL31: =IF(COUNTA($W$22:$AF$22)>0, AK31/COUNTA($W$22:$AF$22), 0)
A32: 10 | B32: Lavínia Ribeiro Sena | C32: B | D32: C | E32: A | F32: B | G32: D | H32: E | I32: C | J32: B | K32: E | L32: C | M32: D | N32: E | O32: B | P32: E | Q32: D | R32: A | S32: C | T32: A | U32: B | V32: C | W32: A | X32: B | Y32: C | Z32: B | AA32: A | AB32: E | AC32: D | AD32: A | AE32: C | AF32: E | AG32: =SUMPRODUCT((C32:AF32<>"")*((C32:AF32=$C$22:$AF$22)+($C$22:$AF$22="*")>0)*($C$22:$AF$22<>"")) | AH32: =IF(COUNTA($C$22:$AF$22)>0, AG32/COUNTA($C$22:$AF$22), 0) | AI32: =SUMPRODUCT((C32:V32<>"")*((C32:V32=$C$22:$V$22)+($C$22:$V$22="*")>0)*($C$22:$V$22<>"")) | AJ32: =IF(COUNTA($C$22:$V$22)>0, AI32/COUNTA($C$22:$V$22), 0) | AK32: =SUMPRODUCT((W32:AF32<>"")*((W32:AF32=$W$22:$AF$22)+($W$22:$AF$22="*")>0)*($W$22:$AF$22<>"")) | AL32: =IF(COUNTA($W$22:$AF$22)>0, AK32/COUNTA($W$22:$AF$22), 0)
A33: 11 | B33: Lavínia Silva Teles | C33: B | D33: C | E33: A | F33: B | G33: B | H33: A | I33: C | J33: D | K33: D | L33: E | M33: B | N33: C | O33: A | P33: D | Q33: D | R33: A | S33: D | T33: B | U33: A | V33: D | W33: A | X33: B | Y33: E | Z33: B | AA33: A | AB33: E | AC33: D | AD33: E | AE33: C | AF33: C | AG33: =SUMPRODUCT((C33:AF33<>"")*((C33:AF33=$C$22:$AF$22)+($C$22:$AF$22="*")>0)*($C$22:$AF$22<>"")) | AH33: =IF(COUNTA($C$22:$AF$22)>0, AG33/COUNTA($C$22:$AF$22), 0) | AI33: =SUMPRODUCT((C33:V33<>"")*((C33:V33=$C$22:$V$22)+($C$22:$V$22="*")>0)*($C$22:$V$22<>"")) | AJ33: =IF(COUNTA($C$22:$V$22)>0, AI33/COUNTA($C$22:$V$22), 0) | AK33: =SUMPRODUCT((W33:AF33<>"")*((W33:AF33=$W$22:$AF$22)+($W$22:$AF$22="*")>0)*($W$22:$AF$22<>"")) | AL33: =IF(COUNTA($W$22:$AF$22)>0, AK33/COUNTA($W$22:$AF$22), 0)
A34: 12 | B34: Lucas Alves Silva Batista | C34: A | D34: A | E34: E | F34: A | G34: C | H34: A | I34: B | J34: C | K34: A | L34: D | M34: C | N34: E | O34: B | P34: A | Q34: E | R34: A | S34: C | T34: C | U34: B | V34: C | W34: C | X34: B | Y34: D | Z34: B | AA34: A | AB34: B | AC34: D | AD34: B | AE34: C | AF34: B | AG34: =SUMPRODUCT((C34:AF34<>"")*((C34:AF34=$C$22:$AF$22)+($C$22:$AF$22="*")>0)*($C$22:$AF$22<>"")) | AH34: =IF(COUNTA($C$22:$AF$22)>0, AG34/COUNTA($C$22:$AF$22), 0) | AI34: =SUMPRODUCT((C34:V34<>"")*((C34:V34=$C$22:$V$22)+($C$22:$V$22="*")>0)*($C$22:$V$22<>"")) | AJ34: =IF(COUNTA($C$22:$V$22)>0, AI34/COUNTA($C$22:$V$22), 0) | AK34: =SUMPRODUCT((W34:AF34<>"")*((W34:AF34=$W$22:$AF$22)+($W$22:$AF$22="*")>0)*($W$22:$AF$22<>"")) | AL34: =IF(COUNTA($W$22:$AF$22)>0, AK34/COUNTA($W$22:$AF$22), 0)
A35: 13 | B35: Luísa Brauer Torres Nacur Quaresma | C35: B | D35: D | E35: E | F35: E | G35: C | H35: A | I35: A | J35: D | K35: C | L35: C | M35: D | N35: A | O35: B | P35: D | Q35: A | R35: E | S35: E | T35: E | U35: B | V35: C | W35: A | X35: B | Y35: D | Z35: B | AA35: A | AB35: E | AC35: D | AD35: E | AE35: B | AF35: C | AG35: =SUMPRODUCT((C35:AF35<>"")*((C35:AF35=$C$22:$AF$22)+($C$22:$AF$22="*")>0)*($C$22:$AF$22<>"")) | AH35: =IF(COUNTA($C$22:$AF$22)>0, AG35/COUNTA($C$22:$AF$22), 0) | AI35: =SUMPRODUCT((C35:V35<>"")*((C35:V35=$C$22:$V$22)+($C$22:$V$22="*")>0)*($C$22:$V$22<>"")) | AJ35: =IF(COUNTA($C$22:$V$22)>0, AI35/COUNTA($C$22:$V$22), 0) | AK35: =SUMPRODUCT((W35:AF35<>"")*((W35:AF35=$W$22:$AF$22)+($W$22:$AF$22="*")>0)*($W$22:$AF$22<>"")) | AL35: =IF(COUNTA($W$22:$AF$22)>0, AK35/COUNTA($W$22:$AF$22), 0)
A36: 14 | B36: Luna Januzzi Quadros | C36: D | D36: B | E36: D | F36: E | G36: B | H36: C | I36: D | J36: A | K36: B | L36: B | M36: D | N36: B | O36: B | P36: E | Q36: A | R36: C | S36: E | T36: A | U36: E | V36: B | W36: C | X36: B | Y36: D | Z36: D | AA36: A | AB36: D | AC36: D | AD36: B | AE36: C | AF36: A | AG36: =SUMPRODUCT((C36:AF36<>"")*((C36:AF36=$C$22:$AF$22)+($C$22:$AF$22="*")>0)*($C$22:$AF$22<>"")) | AH36: =IF(COUNTA($C$22:$AF$22)>0, AG36/COUNTA($C$22:$AF$22), 0) | AI36: =SUMPRODUCT((C36:V36<>"")*((C36:V36=$C$22:$V$22)+($C$22:$V$22="*")>0)*($C$22:$V$22<>"")) | AJ36: =IF(COUNTA($C$22:$V$22)>0, AI36/COUNTA($C$22:$V$22), 0) | AK36: =SUMPRODUCT((W36:AF36<>"")*((W36:AF36=$W$22:$AF$22)+($W$22:$AF$22="*")>0)*($W$22:$AF$22<>"")) | AL36: =IF(COUNTA($W$22:$AF$22)>0, AK36/COUNTA($W$22:$AF$22), 0)
A37: 15 | B37: Maria Cecília Rebouças | C37: E | D37: C | E37: A | F37: E | G37: B | H37: D | I37: E | J37: D | K37: C | L37: C | M37: C | N37: E | O37: B | P37: E | Q37: E | R37: B | S37: E | T37: C | U37: B | V37: D | W37: C | X37: B | Y37: D | Z37: B | AA37: A | AB37: D | AC37: D | AD37: E | AE37: C | AF37: E | AG37: =SUMPRODUCT((C37:AF37<>"")*((C37:AF37=$C$22:$AF$22)+($C$22:$AF$22="*")>0)*($C$22:$AF$22<>"")) | AH37: =IF(COUNTA($C$22:$AF$22)>0, AG37/COUNTA($C$22:$AF$22), 0) | AI37: =SUMPRODUCT((C37:V37<>"")*((C37:V37=$C$22:$V$22)+($C$22:$V$22="*")>0)*($C$22:$V$22<>"")) | AJ37: =IF(COUNTA($C$22:$V$22)>0, AI37/COUNTA($C$22:$V$22), 0) | AK37: =SUMPRODUCT((W37:AF37<>"")*((W37:AF37=$W$22:$AF$22)+($W$22:$AF$22="*")>0)*($W$22:$AF$22<>"")) | AL37: =IF(COUNTA($W$22:$AF$22)>0, AK37/COUNTA($W$22:$AF$22), 0)
A38: 16 | B38: Maria Clara Nogueira Tinoco | C38: C | D38: C | E38: A | F38: D | G38: E | H38: E | I38: C | J38: B | K38: A | L38: A | M38: D | N38: C | O38: E | P38: C | Q38: E | R38: C | S38: C | T38: E | U38: C | V38: B | W38: C | X38: B | Y38: B | Z38: B | AA38: A | AB38: D | AC38: D | AD38: E | AE38: E | AF38: E | AG38: =SUMPRODUCT((C38:AF38<>"")*((C38:AF38=$C$22:$AF$22)+($C$22:$AF$22="*")>0)*($C$22:$AF$22<>"")) | AH38: =IF(COUNTA($C$22:$AF$22)>0, AG38/COUNTA($C$22:$AF$22), 0) | AI38: =SUMPRODUCT((C38:V38<>"")*((C38:V38=$C$22:$V$22)+($C$22:$V$22="*")>0)*($C$22:$V$22<>"")) | AJ38: =IF(COUNTA($C$22:$V$22)>0, AI38/COUNTA($C$22:$V$22), 0) | AK38: =SUMPRODUCT((W38:AF38<>"")*((W38:AF38=$W$22:$AF$22)+($W$22:$AF$22="*")>0)*($W$22:$AF$22<>"")) | AL38: =IF(COUNTA($W$22:$AF$22)>0, AK38/COUNTA($W$22:$AF$22), 0)
... A42: 20 | B42: Tito Teles Machado | C42: C | D42: E | E42: A | F42: B | G42: C | H42: D | I42: A | J42: A | K42: D | L42: B | M42: B | N42: D | O42: A | P42: D | Q42: A | R42: A | S42: B | T42: C | U42: C | V42: D | W42: D | X42: B | Y42: E | Z42: D | AA42: D | AB42: D | AC42: E | AD42: B | AE42: B | AF42: D | AG42: =SUMPRODUCT((C42:AF42<>"")*((C42:AF42=$C$22:$AF$22)+($C$22:$AF$22="*")>0)*($C$22:$AF$22<>"")) | AH42: =IF(COUNTA($C$22:$AF$22)>0, AG42/COUNTA($C$22:$AF$22), 0) | AI42: =SUMPRODUCT((C42:V42<>"")*((C42:V42=$C$22:$V$22)+($C$22:$V$22="*")>0)*($C$22:$V$22<>"")) | AJ42: =IF(COUNTA($C$22:$V$22)>0, AI42/COUNTA($C$22:$V$22), 0) | AK42: =SUMPRODUCT((W42:AF42<>"")*((W42:AF42=$W$22:$AF$22)+($W$22:$AF$22="*")>0)*($W$22:$AF$22<>"")) | AL42: =IF(COUNTA($W$22:$AF$22)>0, AK42/COUNTA($W$22:$AF$22), 0)
A44: TURMA: 8º ANO (7 alunos)
A45: Nº | B45: Nome do Aluno | C45: Q01 | D45: Q02 | E45: Q03 | F45: Q04 | G45: Q05 | H45: Q06 | I45: Q07 | J45: Q08 | K45: Q09 | L45: Q10 | M45: Q11 | N45: Q12 | O45: Q13 | P45: Q14 | Q45: Q15 | R45: Q16 | S45: Q17 | T45: Q18 | U45: Q19 | V45: Q20 | W45: Q21 | X45: Q22 | Y45: Q23 | Z45: Q24 | AA45: Q25 | AB45: Q26 | AC45: Q27 | AD45: Q28 | AE45: Q29 | AF45: Q30 | AG45: Total (30) | AH45: % Geral | AI45: Reading (20) | AJ45: % Reading | AK45: Listening (10) | AL45: % Listening
A46: ★ | B46: [ GABARITO OFICIAL — 8º ANO ] | C46: D | D46: C | E46: B | F46: * | G46: E | H46: E | I46: C | J46: C | K46: E | L46: E | M46: D | N46: B | O46: D | P46: B | Q46: A | R46: C | S46: C | T46: B | U46: A | V46: C | W46: A | X46: B | Y46: D | Z46: B | AA46: D | AB46: C | AC46: C | AD46: C | AE46: D | AF46: A | AG46: =COUNTA(C46:AF46) | AH46: Gabarito | AI46: =COUNTA(C46:V46) | AJ46: Reading | AK46: =COUNTA(W46:AF46) | AL46: Listening
...

Sheet 6º ANO
A1: OBLI 2024.2 (SELETA EDUCAÇÃO) • COOEDUCAR CARLOS CHAGAS — 6º ANO
A2: Q01 a Q20: READING (Compreensão Leitora - 20 pts) | Q21 a Q30: LISTENING (Compreensão Auditiva - 10 pts)
A3: Nº | B3: Nome do Aluno | C3: Q01 | D3: Q02 | E3: Q03 | F3: Q04 | G3: Q05 | H3: Q06 | I3: Q07 | J3: Q08 | K3: Q09 | L3: Q10 | M3: Q11 | N3: Q12 | O3: Q13 | P3: Q14 | Q3: Q15 | R3: Q16 | S3: Q17 | T3: Q18 | U3: Q19 | V3: Q20 | W3: Q21 | X3: Q22 | Y3: Q23 | Z3: Q24 | AA3: Q25 | AB3: Q26 | AC3: Q27 | AD3: Q28 | AE3: Q29 | AF3: Q30 | AG3: Total (30) | AH3: % Geral | AI3: Reading (20) | AJ3: % Reading | AK3: Listening (10) | AL3: % Listening
A4: ★ | B4: [ GABARITO OFICIAL — 6º ANO ] | C4: =IF('Todas as Turmas'!C6="","",'Todas as Turmas'!C6) | D4: =IF('Todas as Turmas'!D6="","",'Todas as Turmas'!D6) | E4: =IF('Todas as Turmas'!E6="","",'Todas as Turmas'!E6) | F4: =IF('Todas as Turmas'!F6="","",'Todas as Turmas'!F6) | G4: =IF('Todas as Turmas'!G6="","",'Todas as Turmas'!G6) | H4: =IF('Todas as Turmas'!H6="","",'Todas as Turmas'!H6) | I4: =IF('Todas as Turmas'!I6="","",'Todas as Turmas'!I6) | J4: =IF('Todas as Turmas'!J6="","",'Todas as Turmas'!J6) | ... AF4: =IF('Todas as Turmas'!AF6="","",'Todas as Turmas'!AF6) | AG4: ='Todas as Turmas'!AG6 | AH4: Gabarito | AI4: ='Todas as Turmas'!AI6 | AJ4: Reading | AK4: ='Todas as Turmas'!AK6 | AL4: Listening
A5: ='Todas as Turmas'!A7 | B5: ='Todas as Turmas'!B7 | C5: =IF('Todas as Turmas'!C7="","",'Todas as Turmas'!C7) | D5: =IF('Todas as Turmas'!D7="","",'Todas as Turmas'!D7) | E5: =IF('Todas as Turmas'!E7="","",'Todas as Turmas'!E7) | F5: =IF('Todas as Turmas'!F7="","",'Todas as Turmas'!F7) | G5: =IF('Todas as Turmas'!G7="","",'Todas as Turmas'!G7) | H5: =IF('Todas as Turmas'!H7="","",'Todas as Turmas'!H7) | I5: =IF('Todas as Turmas'!I7="","",'Todas as Turmas'!I7) | J5: =IF('Todas as Turmas'!J7="","",'Todas as Turmas'!J7) | ... AF5: =IF('Todas as Turmas'!AF7="","",'Todas as Turmas'!AF7) | AG5: ='Todas as Turmas'!AG7 | AH5: ='Todas as Turmas'!AH7 | AI5: ='Todas as Turmas'!AI7 | AJ5: ='Todas as Turmas'!AJ7 | AK5: ='Todas as Turmas'!AK7 | AL5: ='Todas as Turmas'!AL7
A6: ='Todas as Turmas'!A8 | B6: ='Todas as Turmas'!B8 | C6: =IF('Todas as Turmas'!C8="","",'Todas as Turmas'!C8) | D6: =IF('Todas as Turmas'!D8="","",'Todas as Turmas'!D8) | E6: =IF('Todas as Turmas'!E8="","",'Todas as Turmas'!E8) | F6: =IF('Todas as Turmas'!F8="","",'Todas as Turmas'!F8) | G6: =IF('Todas as Turmas'!G8="","",'Todas as Turmas'!G8) | H6: =IF('Todas as Turmas'!H8="","",'Todas as Turmas'!H8) | I6: =IF('Todas as Turmas'!I8="","",'Todas as Turmas'!I8) | J6: =IF('Todas as Turmas'!J8="","",'Todas as Turmas'!J8) | ... AF6: =IF('Todas as Turmas'!AF8="","",'Todas as Turmas'!AF8) | AG6: ='Todas as Turmas'!AG8 | AH6: ='Todas as Turmas'!AH8 | AI6: ='Todas as Turmas'!AI8 | AJ6: ='Todas as Turmas'!AJ8 | AK6: ='Todas as Turmas'!AK8 | AL6: ='Todas as Turmas'!AL8
A7: ='Todas as Turmas'!A9 | B7: ='Todas as Turmas'!B9 | C7: =IF('Todas as Turmas'!C9="","",'Todas as Turmas'!C9) | D7: =IF('Todas as Turmas'!D9="","",'Todas as Turmas'!D9) | E7: =IF('Todas as Turmas'!E9="","",'Todas as Turmas'!E9) | F7: =IF('Todas as Turmas'!F9="","",'Todas as Turmas'!F9) | G7: =IF('Todas as Turmas'!G9="","",'Todas as Turmas'!G9) | H7: =IF('Todas as Turmas'!H9="","",'Todas as Turmas'!H9) | I7: =IF('Todas as Turmas'!I9="","",'Todas as Turmas'!I9) | J7: =IF('Todas as Turmas'!J9="","",'Todas as Turmas'!J9) | ... AF7: =IF('Todas as Turmas'!AF9="","",'Todas as Turmas'!AF9) | AG7: ='Todas as Turmas'!AG9 | AH7: ='Todas as Turmas'!AH9 | AI7: ='Todas as Turmas'!AI9 | AJ7: ='Todas as Turmas'!AJ9 | AK7: ='Todas as Turmas'!AK9 | AL7: ='Todas as Turmas'!AL9
A8: ='Todas as Turmas'!A10 | B8: ='Todas as Turmas'!B10 | C8: =IF('Todas as Turmas'!C10="","",'Todas as Turmas'!C10) | D8: =IF('Todas as Turmas'!D10="","",'Todas as Turmas'!D10) | E8: =IF('Todas as Turmas'!E10="","",'Todas as Turmas'!E10) | F8: =IF('Todas as Turmas'!F10="","",'Todas as Turmas'!F10) | G8: =IF('Todas as Turmas'!G10="","",'Todas as Turmas'!G10) | H8: =IF('Todas as Turmas'!H10="","",'Todas as Turmas'!H10) | I8: =IF('Todas as Turmas'!I10="","",'Todas as Turmas'!I10) | J8: =IF('Todas as Turmas'!J10="","",'Todas as Turmas'!J10) | ... AF8: =IF('Todas as Turmas'!AF10="","",'Todas as Turmas'!AF10) | AG8: ='Todas as Turmas'!AG10 | AH8: ='Todas as Turmas'!AH10 | AI8: ='Todas as Turmas'!AI10 | AJ8: ='Todas as Turmas'!AJ10 | AK8: ='Todas as Turmas'!AK10 | AL8: ='Todas as Turmas'!AL10
A9: ='Todas as Turmas'!A11 | B9: ='Todas as Turmas'!B11 | C9: =IF('Todas as Turmas'!C11="","",'Todas as Turmas'!C11) | D9: =IF('Todas as Turmas'!D11="","",'Todas as Turmas'!D11) | E9: =IF('Todas as Turmas'!E11="","",'Todas as Turmas'!E11) | F9: =IF('Todas as Turmas'!F11="","",'Todas as Turmas'!F11) | G9: =IF('Todas as Turmas'!G11="","",'Todas as Turmas'!G11) | H9: =IF('Todas as Turmas'!H11="","",'Todas as Turmas'!H11) | I9: =IF('Todas as Turmas'!I11="","",'Todas as Turmas'!I11) | J9: =IF('Todas as Turmas'!J11="","",'Todas as Turmas'!J11) | ... AF9: =IF('Todas as Turmas'!AF11="","",'Todas as Turmas'!AF11) | AG9: ='Todas as Turmas'!AG11 | AH9: ='Todas as Turmas'!AH11 | AI9: ='Todas as Turmas'!AI11 | AJ9: ='Todas as Turmas'!AJ11 | AK9: ='Todas as Turmas'!AK11 | AL9: ='Todas as Turmas'!AL11
A10: ='Todas as Turmas'!A12 | B10: ='Todas as Turmas'!B12 | C10: =IF('Todas as Turmas'!C12="","",'Todas as Turmas'!C12) | D10: =IF('Todas as Turmas'!D12="","",'Todas as Turmas'!D12) | E10: =IF('Todas as Turmas'!E12="","",'Todas as Turmas'!E12) | F10: =IF('Todas as Turmas'!F12="","",'Todas as Turmas'!F12) | G10: =IF('Todas as Turmas'!G12="","",'Todas as Turmas'!G12) | H10: =IF('Todas as Turmas'!H12="","",'Todas as Turmas'!H12) | I10: =IF('Todas as Turmas'!I12="","",'Todas as Turmas'!I12) | J10: =IF('Todas as Turmas'!J12="","",'Todas as Turmas'!J12) | ... AF10: =IF('Todas as Turmas'!AF12="","",'Todas as Turmas'!AF12) | AG10: ='Todas as Turmas'!AG12 | AH10: ='Todas as Turmas'!AH12 | AI10: ='Todas as Turmas'!AI12 | AJ10: ='Todas as Turmas'!AJ12 | AK10: ='Todas as Turmas'!AK12 | AL10: ='Todas as Turmas'!AL12
A11: ='Todas as Turmas'!A13 | B11: ='Todas as Turmas'!B13 | C11: =IF('Todas as Turmas'!C13="","",'Todas as Turmas'!C13) | D11: =IF('Todas as Turmas'!D13="","",'Todas as Turmas'!D13) | E11: =IF('Todas as Turmas'!E13="","",'Todas as Turmas'!E13) | F11: =IF('Todas as Turmas'!F13="","",'Todas as Turmas'!F13) | G11: =IF('Todas as Turmas'!G13="","",'Todas as Turmas'!G13) | H11: =IF('Todas as Turmas'!H13="","",'Todas as Turmas'!H13) | I11: =IF('Todas as Turmas'!I13="","",'Todas as Turmas'!I13) | J11: =IF('Todas as Turmas'!J13="","",'Todas as Turmas'!J13) | ... AF11: =IF('Todas as Turmas'!AF13="","",'Todas as Turmas'!AF13) | AG11: ='Todas as Turmas'!AG13 | AH11: ='Todas as Turmas'!AH13 | AI11: ='Todas as Turmas'!AI13 | AJ11: ='Todas as Turmas'!AJ13 | AK11: ='Todas as Turmas'!AK13 | AL11: ='Todas as Turmas'!AL13
A12: ='Todas as Turmas'!A14 | B12: ='Todas as Turmas'!B14 | C12: =IF('Todas as Turmas'!C14="","",'Todas as Turmas'!C14) | D12: =IF('Todas as Turmas'!D14="","",'Todas as Turmas'!D14) | E12: =IF('Todas as Turmas'!E14="","",'Todas as Turmas'!E14) | F12: =IF('Todas as Turmas'!F14="","",'Todas as Turmas'!F14) | G12: =IF('Todas as Turmas'!G14="","",'Todas as Turmas'!G14) | H12: =IF('Todas as Turmas'!H14="","",'Todas as Turmas'!H14) | I12: =IF('Todas as Turmas'!I14="","",'Todas as Turmas'!I14) | J12: =IF('Todas as Turmas'!J14="","",'Todas as Turmas'!J14) | ... AF12: =IF('Todas as Turmas'!AF14="","",'Todas as Turmas'!AF14) | AG12: ='Todas as Turmas'!AG14 | AH12: ='Todas as Turmas'!AH14 | AI12: ='Todas as Turmas'!AI14 | AJ12: ='Todas as Turmas'!AJ14 | AK12: ='Todas as Turmas'!AK14 | AL12: ='Todas as Turmas'!AL14
A13: ='Todas as Turmas'!A15 | B13: ='Todas as Turmas'!B15 | C13: =IF('Todas as Turmas'!C15="","",'Todas as Turmas'!C15) | D13: =IF('Todas as Turmas'!D15="","",'Todas as Turmas'!D15) | E13: =IF('Todas as Turmas'!E15="","",'Todas as Turmas'!E15) | F13: =IF('Todas as Turmas'!F15="","",'Todas as Turmas'!F15) | G13: =IF('Todas as Turmas'!G15="","",'Todas as Turmas'!G15) | H13: =IF('Todas as Turmas'!H15="","",'Todas as Turmas'!H15) | I13: =IF('Todas as Turmas'!I15="","",'Todas as Turmas'!I15) | J13: =IF('Todas as Turmas'!J15="","",'Todas as Turmas'!J15) | ... AF13: =IF('Todas as Turmas'!AF15="","",'Todas as Turmas'!AF15) | AG13: ='Todas as Turmas'!AG15 | AH13: ='Todas as Turmas'!AH15 | AI13: ='Todas as Turmas'!AI15 | AJ13: ='Todas as Turmas'!AJ15 | AK13: ='Todas as Turmas'!AK15 | AL13: ='Todas as Turmas'!AL15
A14: ='Todas as Turmas'!A16 | B14: ='Todas as Turmas'!B16 | C14: =IF('Todas as Turmas'!C16="","",'Todas as Turmas'!C16) | D14: =IF('Todas as Turmas'!D16="","",'Todas as Turmas'!D16) | E14: =IF('Todas as Turmas'!E16="","",'Todas as Turmas'!E16) | F14: =IF('Todas as Turmas'!F16="","",'Todas as Turmas'!F16) | G14: =IF('Todas as Turmas'!G16="","",'Todas as Turmas'!G16) | H14: =IF('Todas as Turmas'!H16="","",'Todas as Turmas'!H16) | I14: =IF('Todas as Turmas'!I16="","",'Todas as Turmas'!I16) | J14: =IF('Todas as Turmas'!J16="","",'Todas as Turmas'!J16) | ... AF14: =IF('Todas as Turmas'!AF16="","",'Todas as Turmas'!AF16) | AG14: ='Todas as Turmas'!AG16 | AH14: ='Todas as Turmas'!AH16 | AI14: ='Todas as Turmas'!AI16 | AJ14: ='Todas as Turmas'!AJ16 | AK14: ='Todas as Turmas'!AK16 | AL14: ='Todas as Turmas'!AL16
A15: ='Todas as Turmas'!A17 | B15: ='Todas as Turmas'!B17 | C15: =IF('Todas as Turmas'!C17="","",'Todas as Turmas'!C17) | D15: =IF('Todas as Turmas'!D17="","",'Todas as Turmas'!D17) | E15: =IF('Todas as Turmas'!E17="","",'Todas as Turmas'!E17) | F15: =IF('Todas as Turmas'!F17="","",'Todas as Turmas'!F17) | G15: =IF('Todas as Turmas'!G17="","",'Todas as Turmas'!G17) | H15: =IF('Todas as Turmas'!H17="","",'Todas as Turmas'!H17) | I15: =IF('Todas as Turmas'!I17="","",'Todas as Turmas'!I17) | J15: =IF('Todas as Turmas'!J17="","",'Todas as Turmas'!J17) | ... AF15: =IF('Todas as Turmas'!AF17="","",'Todas as Turmas'!AF17) | AG15: ='Todas as Turmas'!AG17 | AH15: ='Todas as Turmas'!AH17 | AI15: ='Todas as Turmas'!AI17 | AJ15: ='Todas as Turmas'!AJ17 | AK15: ='Todas as Turmas'!AK17 | AL15: ='Todas as Turmas'!AL17
A16: ='Todas as Turmas'!A18 | B16: ='Todas as Turmas'!B18 | C16: =IF('Todas as Turmas'!C18="","",'Todas as Turmas'!C18) | D16: =IF('Todas as Turmas'!D18="","",'Todas as Turmas'!D18) | E16: =IF('Todas as Turmas'!E18="","",'Todas as Turmas'!E18) | F16: =IF('Todas as Turmas'!F18="","",'Todas as Turmas'!F18) | G16: =IF('Todas as Turmas'!G18="","",'Todas as Turmas'!G18) | H16: =IF('Todas as Turmas'!H18="","",'Todas as Turmas'!H18) | I16: =IF('Todas as Turmas'!I18="","",'Todas as Turmas'!I18) | J16: =IF('Todas as Turmas'!J18="","",'Todas as Turmas'!J18) | ... AF16: =IF('Todas as Turmas'!AF18="","",'Todas as Turmas'!AF18) | AG16: ='Todas as Turmas'!AG18 | AH16: ='Todas as Turmas'!AH18 | AI16: ='Todas as Turmas'!AI18 | AJ16: ='Todas as Turmas'!AJ18 | AK16: ='Todas as Turmas'!AK18 | AL16: ='Todas as Turmas'!AL18

Sheet 7º ANO
A1: OBLI 2024.2 (SELETA EDUCAÇÃO) • COOEDUCAR CARLOS CHAGAS — 7º ANO
A2: Q01 a Q20: READING (Compreensão Leitora - 20 pts) | Q21 a Q30: LISTENING (Compreensão Auditiva - 10 pts)
A3: Nº | B3: Nome do Aluno | C3: Q01 | D3: Q02 | E3: Q03 | F3: Q04 | G3: Q05 | H3: Q06 | I3: Q07 | J3: Q08 | K3: Q09 | L3: Q10 | M3: Q11 | N3: Q12 | O3: Q13 | P3: Q14 | Q3: Q15 | R3: Q16 | S3: Q17 | T3: Q18 | U3: Q19 | V3: Q20 | W3: Q21 | X3: Q22 | Y3: Q23 | Z3: Q24 | AA3: Q25 | AB3: Q26 | AC3: Q27 | AD3: Q28 | AE3: Q29 | AF3: Q30 | AG3: Total (30) | AH3: % Geral | AI3: Reading (20) | AJ3: % Reading | AK3: Listening (10) | AL3: % Listening
A4: ★ | B4: [ GABARITO OFICIAL — 7º ANO ] | C4: =IF('Todas as Turmas'!C22="","",'Todas as Turmas'!C22) | D4: =IF('Todas as Turmas'!D22="","",'Todas as Turmas'!D22) | E4: =IF('Todas as Turmas'!E22="","",'Todas as Turmas'!E22) | F4: =IF('Todas as Turmas'!F22="","",'Todas as Turmas'!F22) | G4: =IF('Todas as Turmas'!G22="","",'Todas as Turmas'!G22) | H4: =IF('Todas as Turmas'!H22="","",'Todas as Turmas'!H22) | I4: =IF('Todas as Turmas'!I22="","",'Todas as Turmas'!I22) | J4: =IF('Todas as Turmas'!J22="","",'Todas as Turmas'!J22) | ... AF4: =IF('Todas as Turmas'!AF22="","",'Todas as Turmas'!AF22) | AG4: ='Todas as Turmas'!AG22 | AH4: Gabarito | AI4: ='Todas as Turmas'!AI22 | AJ4: Reading | AK4: ='Todas as Turmas'!AK22 | AL4: Listening
A5: ='Todas as Turmas'!A23 | B5: ='Todas as Turmas'!B23 | C5: =IF('Todas as Turmas'!C23="","",'Todas as Turmas'!C23) | D5: =IF('Todas as Turmas'!D23="","",'Todas as Turmas'!D23) | E5: =IF('Todas as Turmas'!E23="","",'Todas as Turmas'!E23) | F5: =IF('Todas as Turmas'!F23="","",'Todas as Turmas'!F23) | G5: =IF('Todas as Turmas'!G23="","",'Todas as Turmas'!G23) | H5: =IF('Todas as Turmas'!H23="","",'Todas as Turmas'!H23) | I5: =IF('Todas as Turmas'!I23="","",'Todas as Turmas'!I23) | J5: =IF('Todas as Turmas'!J23="","",'Todas as Turmas'!J23) | ... AF5: =IF('Todas as Turmas'!AF23="","",'Todas as Turmas'!AF23) | AG5: ='Todas as Turmas'!AG23 | AH5: ='Todas as Turmas'!AH23 | AI5: ='Todas as Turmas'!AI23 | AJ5: ='Todas as Turmas'!AJ23 | AK5: ='Todas as Turmas'!AK23 | AL5: ='Todas as Turmas'!AL23
A6: ='Todas as Turmas'!A24 | B6: ='Todas as Turmas'!B24 | C6: =IF('Todas as Turmas'!C24="","",'Todas as Turmas'!C24) | D6: =IF('Todas as Turmas'!D24="","",'Todas as Turmas'!D24) | E6: =IF('Todas as Turmas'!E24="","",'Todas as Turmas'!E24) | F6: =IF('Todas as Turmas'!F24="","",'Todas as Turmas'!F24) | G6: =IF('Todas as Turmas'!G24="","",'Todas as Turmas'!G24) | H6: =IF('Todas as Turmas'!H24="","",'Todas as Turmas'!H24) | I6: =IF('Todas as Turmas'!I24="","",'Todas as Turmas'!I24) | J6: =IF('Todas as Turmas'!J24="","",'Todas as Turmas'!J24) | ... AF6: =IF('Todas as Turmas'!AF24="","",'Todas as Turmas'!AF24) | AG6: ='Todas as Turmas'!AG24 | AH6: ='Todas as Turmas'!AH24 | AI6: ='Todas as Turmas'!AI24 | AJ6: ='Todas as Turmas'!AJ24 | AK6: ='Todas as Turmas'!AK24 | AL6: ='Todas as Turmas'!AL24
A7: ='Todas as Turmas'!A25 | B7: ='Todas as Turmas'!B25 | C7: =IF('Todas as Turmas'!C25="","",'Todas as Turmas'!C25) | D7: =IF('Todas as Turmas'!D25="","",'Todas as Turmas'!D25) | E7: =IF('Todas as Turmas'!E25="","",'Todas as Turmas'!E25) | F7: =IF('Todas as Turmas'!F25="","",'Todas as Turmas'!F25) | G7: =IF('Todas as Turmas'!G25="","",'Todas as Turmas'!G25) | H7: =IF('Todas as Turmas'!H25="","",'Todas as Turmas'!H25) | I7: =IF('Todas as Turmas'!I25="","",'Todas as Turmas'!I25) | J7: =IF('Todas as Turmas'!J25="","",'Todas as Turmas'!J25) | ... AF7: =IF('Todas as Turmas'!AF25="","",'Todas as Turmas'!AF25) | AG7: ='Todas as Turmas'!AG25 | AH7: ='Todas as Turmas'!AH25 | AI7: ='Todas as Turmas'!AI25 | AJ7: ='Todas as Turmas'!AJ25 | AK7: ='Todas as Turmas'!AK25 | AL7: ='Todas as Turmas'!AL25
A8: ='Todas as Turmas'!A26 | B8: ='Todas as Turmas'!B26 | C8: =IF('Todas as Turmas'!C26="","",'Todas as Turmas'!C26) | D8: =IF('Todas as Turmas'!D26="","",'Todas as Turmas'!D26) | E8: =IF('Todas as Turmas'!E26="","",'Todas as Turmas'!E26) | F8: =IF('Todas as Turmas'!F26="","",'Todas as Turmas'!F26) | G8: =IF('Todas as Turmas'!G26="","",'Todas as Turmas'!G26) | H8: =IF('Todas as Turmas'!H26="","",'Todas as Turmas'!H26) | I8: =IF('Todas as Turmas'!I26="","",'Todas as Turmas'!I26) | J8: =IF('Todas as Turmas'!J26="","",'Todas as Turmas'!J26) | ... AF8: =IF('Todas as Turmas'!AF26="","",'Todas as Turmas'!AF26) | AG8: ='Todas as Turmas'!AG26 | AH8: ='Todas as Turmas'!AH26 | AI8: ='Todas as Turmas'!AI26 | AJ8: ='Todas as Turmas'!AJ26 | AK8: ='Todas as Turmas'!AK26 | AL8: ='Todas as Turmas'!AL26
A9: ='Todas as Turmas'!A27 | B9: ='Todas as Turmas'!B27 | C9: =IF('Todas as Turmas'!C27="","",'Todas as Turmas'!C27) | D9: =IF('Todas as Turmas'!D27="","",'Todas as Turmas'!D27) | E9: =IF('Todas as Turmas'!E27="","",'Todas as Turmas'!E27) | F9: =IF('Todas as Turmas'!F27="","",'Todas as Turmas'!F27) | G9: =IF('Todas as Turmas'!G27="","",'Todas as Turmas'!G27) | H9: =IF('Todas as Turmas'!H27="","",'Todas as Turmas'!H27) | I9: =IF('Todas as Turmas'!I27="","",'Todas as Turmas'!I27) | J9: =IF('Todas as Turmas'!J27="","",'Todas as Turmas'!J27) | ... AF9: =IF('Todas as Turmas'!AF27="","",'Todas as Turmas'!AF27) | AG9: ='Todas as Turmas'!AG27 | AH9: ='Todas as Turmas'!AH27 | AI9: ='Todas as Turmas'!AI27 | AJ9: ='Todas as Turmas'!AJ27 | AK9: ='Todas as Turmas'!AK27 | AL9: ='Todas as Turmas'!AL27
A10: ='Todas as Turmas'!A28 | B10: ='Todas as Turmas'!B28 | C10: =IF('Todas as Turmas'!C28="","",'Todas as Turmas'!C28) | D10: =IF('Todas as Turmas'!D28="","",'Todas as Turmas'!D28) | E10: =IF('Todas as Turmas'!E28="","",'Todas as Turmas'!E28) | F10: =IF('Todas as Turmas'!F28="","",'Todas as Turmas'!F28) | G10: =IF('Todas as Turmas'!G28="","",'Todas as Turmas'!G28) | H10: =IF('Todas as Turmas'!H28="","",'Todas as Turmas'!H28) | I10: =IF('Todas as Turmas'!I28="","",'Todas as Turmas'!I28) | J10: =IF('Todas as Turmas'!J28="","",'Todas as Turmas'!J28) | ... AF10: =IF('Todas as Turmas'!AF28="","",'Todas as Turmas'!AF28) | AG10: ='Todas as Turmas'!AG28 | AH10: ='Todas as Turmas'!AH28 | AI10: ='Todas as Turmas'!AI28 | AJ10: ='Todas as Turmas'!AJ28 | AK10: ='Todas as Turmas'!AK28 | AL10: ='Todas as Turmas'!AL28
A11: ='Todas as Turmas'!A29 | B11: ='Todas as Turmas'!B29 | C11: =IF('Todas as Turmas'!C29="","",'Todas as Turmas'!C29) | D11: =IF('Todas as Turmas'!D29="","",'Todas as Turmas'!D29) | E11: =IF('Todas as Turmas'!E29="","",'Todas as Turmas'!E29) | F11: =IF('Todas as Turmas'!F29="","",'Todas as Turmas'!F29) | G11: =IF('Todas as Turmas'!G29="","",'Todas as Turmas'!G29) | H11: =IF('Todas as Turmas'!H29="","",'Todas as Turmas'!H29) | I11: =IF('Todas as Turmas'!I29="","",'Todas as Turmas'!I29) | J11: =IF('Todas as Turmas'!J29="","",'Todas as Turmas'!J29) | ... AF11: =IF('Todas as Turmas'!AF29="","",'Todas as Turmas'!AF29) | AG11: ='Todas as Turmas'!AG29 | AH11: ='Todas as Turmas'!AH29 | AI11: ='Todas as Turmas'!AI29 | AJ11: ='Todas as Turmas'!AJ29 | AK11: ='Todas as Turmas'!AK29 | AL11: ='Todas as Turmas'!AL29
A12: ='Todas as Turmas'!A30 | B12: ='Todas as Turmas'!B30 | C12: =IF('Todas as Turmas'!C30="","",'Todas as Turmas'!C30) | D12: =IF('Todas as Turmas'!D30="","",'Todas as Turmas'!D30) | E12: =IF('Todas as Turmas'!E30="","",'Todas as Turmas'!E30) | F12: =IF('Todas as Turmas'!F30="","",'Todas as Turmas'!F30) | G12: =IF('Todas as Turmas'!G30="","",'Todas as Turmas'!G30) | H12: =IF('Todas as Turmas'!H30="","",'Todas as Turmas'!H30) | I12: =IF('Todas as Turmas'!I30="","",'Todas as Turmas'!I30) | J12: =IF('Todas as Turmas'!J30="","",'Todas as Turmas'!J30) | ... AF12: =IF('Todas as Turmas'!AF30="","",'Todas as Turmas'!AF30) | AG12: ='Todas as Turmas'!AG30 | AH12: ='Todas as Turmas'!AH30 | AI12: ='Todas as Turmas'!AI30 | AJ12: ='Todas as Turmas'!AJ30 | AK12: ='Todas as Turmas'!AK30 | AL12: ='Todas as Turmas'!AL30
A13: ='Todas as Turmas'!A31 | B13: ='Todas as Turmas'!B31 | C13: =IF('Todas as Turmas'!C31="","",'Todas as Turmas'!C31) | D13: =IF('Todas as Turmas'!D31="","",'Todas as Turmas'!D31) | E13: =IF('Todas as Turmas'!E31="","",'Todas as Turmas'!E31) | F13: =IF('Todas as Turmas'!F31="","",'Todas as Turmas'!F31) | G13: =IF('Todas as Turmas'!G31="","",'Todas as Turmas'!G31) | H13: =IF('Todas as Turmas'!H31="","",'Todas as Turmas'!H31) | I13: =IF('Todas as Turmas'!I31="","",'Todas as Turmas'!I31) | J13: =IF('Todas as Turmas'!J31="","",'Todas as Turmas'!J31) | ... AF13: =IF('Todas as Turmas'!AF31="","",'Todas as Turmas'!AF31) | AG13: ='Todas as Turmas'!AG31 | AH13: ='Todas as Turmas'!AH31 | AI13: ='Todas as Turmas'!AI31 | AJ13: ='Todas as Turmas'!AJ31 | AK13: ='Todas as Turmas'!AK31 | AL13: ='Todas as Turmas'!AL31
A14: ='Todas as Turmas'!A32 | B14: ='Todas as Turmas'!B32 | C14: =IF('Todas as Turmas'!C32="","",'Todas as Turmas'!C32) | D14: =IF('Todas as Turmas'!D32="","",'Todas as Turmas'!D32) | E14: =IF('Todas as Turmas'!E32="","",'Todas as Turmas'!E32) | F14: =IF('Todas as Turmas'!F32="","",'Todas as Turmas'!F32) | G14: =IF('Todas as Turmas'!G32="","",'Todas as Turmas'!G32) | H14: =IF('Todas as Turmas'!H32="","",'Todas as Turmas'!H32) | I14: =IF('Todas as Turmas'!I32="","",'Todas as Turmas'!I32) | J14: =IF('Todas as Turmas'!J32="","",'Todas as Turmas'!J32) | ... AF14: =IF('Todas as Turmas'!AF32="","",'Todas as Turmas'!AF32) | AG14: ='Todas as Turmas'!AG32 | AH14: ='Todas as Turmas'!AH32 | AI14: ='Todas as Turmas'!AI32 | AJ14: ='Todas as Turmas'!AJ32 | AK14: ='Todas as Turmas'!AK32 | AL14: ='Todas as Turmas'!AL32
A15: ='Todas as Turmas'!A33 | B15: ='Todas as Turmas'!B33 | C15: =IF('Todas as Turmas'!C33="","",'Todas as Turmas'!C33) | D15: =IF('Todas as Turmas'!D33="","",'Todas as Turmas'!D33) | E15: =IF('Todas as Turmas'!E33="","",'Todas as Turmas'!E33) | F15: =IF('Todas as Turmas'!F33="","",'Todas as Turmas'!F33) | G15: =IF('Todas as Turmas'!G33="","",'Todas as Turmas'!G33) | H15: =IF('Todas as Turmas'!H33="","",'Todas as Turmas'!H33) | I15: =IF('Todas as Turmas'!I33="","",'Todas as Turmas'!I33) | J15: =IF('Todas as Turmas'!J33="","",'Todas as Turmas'!J33) | ... AF15: =IF('Todas as Turmas'!AF33="","",'Todas as Turmas'!AF33) | AG15: ='Todas as Turmas'!AG33 | AH15: ='Todas as Turmas'!AH33 | AI15: ='Todas as Turmas'!AI33 | AJ15: ='Todas as Turmas'!AJ33 | AK15: ='Todas as Turmas'!AK33 | AL15: ='Todas as Turmas'!AL33
A16: ='Todas as Turmas'!A34 | B16: ='Todas as Turmas'!B34 | C16: =IF('Todas as Turmas'!C34="","",'Todas as Turmas'!C34) | D16: =IF('Todas as Turmas'!D34="","",'Todas as Turmas'!D34) | E16: =IF('Todas as Turmas'!E34="","",'Todas as Turmas'!E34) | F16: =IF('Todas as Turmas'!F34="","",'Todas as Turmas'!F34) | G16: =IF('Todas as Turmas'!G34="","",'Todas as Turmas'!G34) | H16: =IF('Todas as Turmas'!H34="","",'Todas as Turmas'!H34) | I16: =IF('Todas as Turmas'!I34="","",'Todas as Turmas'!I34) | J16: =IF('Todas as Turmas'!J34="","",'Todas as Turmas'!J34) | ... AF16: =IF('Todas as Turmas'!AF34="","",'Todas as Turmas'!AF34) | AG16: ='Todas as Turmas'!AG34 | AH16: ='Todas as Turmas'!AH34 | AI16: ='Todas as Turmas'!AI34 | AJ16: ='Todas as Turmas'!AJ34 | AK16: ='Todas as Turmas'!AK34 | AL16: ='Todas as Turmas'!AL34
... A24: ='Todas as Turmas'!A42 | B24: ='Todas as Turmas'!B42 | C24: =IF('Todas as Turmas'!C42="","",'Todas as Turmas'!C42) | D24: =IF('Todas as Turmas'!D42="","",'Todas as Turmas'!D42) | E24: =IF('Todas as Turmas'!E42="","",'Todas as Turmas'!E42) | F24: =IF('Todas as Turmas'!F42="","",'Todas as Turmas'!F42) | G24: =IF('Todas as Turmas'!G42="","",'Todas as Turmas'!G42) | H24: =IF('Todas as Turmas'!H42="","",'Todas as Turmas'!H42) | I24: =IF('Todas as Turmas'!I42="","",'Todas as Turmas'!I42) | J24: =IF('Todas as Turmas'!J42="","",'Todas as Turmas'!J42) | ... AF24: =IF('Todas as Turmas'!AF42="","",'Todas as Turmas'!AF42) | AG24: ='Todas as Turmas'!AG42 | AH24: ='Todas as Turmas'!AH42 | AI24: ='Todas as Turmas'!AI42 | AJ24: ='Todas as Turmas'!AJ42 | AK24: ='Todas as Turmas'!AK42 | AL24: ='Todas as Turmas'!AL42

Sheet 8º ANO
A1: OBLI 2024.2 (SELETA EDUCAÇÃO) • COOEDUCAR CARLOS CHAGAS — 8º ANO
A2: Q01 a Q20: READING (Compreensão Leitora - 20 pts) | Q21 a Q30: LISTENING (Compreensão Auditiva - 10 pts)
A3: Nº | B3: Nome do Aluno | C3: Q01 | D3: Q02 | E3: Q03 | F3: Q04 | G3: Q05 | H3: Q06 | I3: Q07 | J3: Q08 | K3: Q09 | L3: Q10 | M3: Q11 | N3: Q12 | O3: Q13 | P3: Q14 | Q3: Q15 | R3: Q16 | S3: Q17 | T3: Q18 | U3: Q19 | V3: Q20 | W3: Q21 | X3: Q22 | Y3: Q23 | Z3: Q24 | AA3: Q25 | AB3: Q26 | AC3: Q27 | AD3: Q28 | AE3: Q29 | AF3: Q30 | AG3: Total (30) | AH3: % Geral | AI3: Reading (20) | AJ3: % Reading | AK3: Listening (10) | AL3: % Listening
A4: ★ | B4: [ GABARITO OFICIAL — 8º ANO ] | C4: =IF('Todas as Turmas'!C46="","",'Todas as Turmas'!C46) | D4: =IF('Todas as Turmas'!D46="","",'Todas as Turmas'!D46) | E4: =IF('Todas as Turmas'!E46="","",'Todas as Turmas'!E46) | F4: =IF('Todas as Turmas'!F46="","",'Todas as Turmas'!F46) | G4: =IF('Todas as Turmas'!G46="","",'Todas as Turmas'!G46) | H4: =IF('Todas as Turmas'!H46="","",'Todas as Turmas'!H46) | I4: =IF('Todas as Turmas'!I46="","",'Todas as Turmas'!I46) | J4: =IF('Todas as Turmas'!J46="","",'Todas as Turmas'!J46) | ... AF4: =IF('Todas as Turmas'!AF46="","",'Todas as Turmas'!AF46) | AG4: ='Todas as Turmas'!AG46 | AH4: Gabarito | AI4: ='Todas as Turmas'!AI46 | AJ4: Reading | AK4: ='Todas as Turmas'!AK46 | AL4: Listening
A5: ='Todas as Turmas'!A47 | B5: ='Todas as Turmas'!B47 | C5: =IF('Todas as Turmas'!C47="","",'Todas as Turmas'!C47) | D5: =IF('Todas as Turmas'!D47="","",'Todas as Turmas'!D47) | E5: =IF('Todas as Turmas'!E47="","",'Todas as Turmas'!E47) | F5: =IF('Todas as Turmas'!F47="","",'Todas as Turmas'!F47) | G5: =IF('Todas as Turmas'!G47="","",'Todas as Turmas'!G47) | H5: =IF('Todas as Turmas'!H47="","",'Todas as Turmas'!H47) | I5: =IF('Todas as Turmas'!I47="","",'Todas as Turmas'!I47) | J5: =IF('Todas as Turmas'!J47="","",'Todas as Turmas'!J47) | ... AF5: =IF('Todas as Turmas'!AF47="","",'Todas as Turmas'!AF47) | AG5: ='Todas as Turmas'!AG47 | AH5: ='Todas as Turmas'!AH47 | AI5: ='Todas as Turmas'!AI47 | AJ5: ='Todas as Turmas'!AJ47 | AK5: ='Todas as Turmas'!AK47 | AL5: ='Todas as Turmas'!AL47
A6: ='Todas as Turmas'!A48 | B6: ='Todas as Turmas'!B48 | C6: =IF('Todas as Turmas'!C48="","",'Todas as Turmas'!C48) | D6: =IF('Todas as Turmas'!D48="","",'Todas as Turmas'!D48) | E6: =IF('Todas as Turmas'!E48="","",'Todas as Turmas'!E48) | F6: =IF('Todas as Turmas'!F48="","",'Todas as Turmas'!F48) | G6: =IF('Todas as Turmas'!G48="","",'Todas as Turmas'!G48) | H6: =IF('Todas as Turmas'!H48="","",'Todas as Turmas'!H48) | I6: =IF('Todas as Turmas'!I48="","",'Todas as Turmas'!I48) | J6: =IF('Todas as Turmas'!J48="","",'Todas as Turmas'!J48) | ... AF6: =IF('Todas as Turmas'!AF48="","",'Todas as Turmas'!AF48) | AG6: ='Todas as Turmas'!AG48 | AH6: ='Todas as Turmas'!AH48 | AI6: ='Todas as Turmas'!AI48 | AJ6: ='Todas as Turmas'!AJ48 | AK6: ='Todas as Turmas'!AK48 | AL6: ='Todas as Turmas'!AL48
A7: ='Todas as Turmas'!A49 | B7: ='Todas as Turmas'!B49 | C7: =IF('Todas as Turmas'!C49="","",'Todas as Turmas'!C49) | D7: =IF('Todas as Turmas'!D49="","",'Todas as Turmas'!D49) | E7: =IF('Todas as Turmas'!E49="","",'Todas as Turmas'!E49) | F7: =IF('Todas as Turmas'!F49="","",'Todas as Turmas'!F49) | G7: =IF('Todas as Turmas'!G49="","",'Todas as Turmas'!G49) | H7: =IF('Todas as Turmas'!H49="","",'Todas as Turmas'!H49) | I7: =IF('Todas as Turmas'!I49="","",'Todas as Turmas'!I49) | J7: =IF('Todas as Turmas'!J49="","",'Todas as Turmas'!J49) | ... AF7: =IF('Todas as Turmas'!AF49="","",'Todas as Turmas'!AF49) | AG7: ='Todas as Turmas'!AG49 | AH7: ='Todas as Turmas'!AH49 | AI7: ='Todas as Turmas'!AI49 | AJ7: ='Todas as Turmas'!AJ49 | AK7: ='Todas as Turmas'!AK49 | AL7: ='Todas as Turmas'!AL49
A8: ='Todas as Turmas'!A50 | B8: ='Todas as Turmas'!B50 | C8: =IF('Todas as Turmas'!C50="","",'Todas as Turmas'!C50) | D8: =IF('Todas as Turmas'!D50="","",'Todas as Turmas'!D50) | E8: =IF('Todas as Turmas'!E50="","",'Todas as Turmas'!E50) | F8: =IF('Todas as Turmas'!F50="","",'Todas as Turmas'!F50) | G8: =IF('Todas as Turmas'!G50="","",'Todas as Turmas'!G50) | H8: =IF('Todas as Turmas'!H50="","",'Todas as Turmas'!H50) | I8: =IF('Todas as Turmas'!I50="","",'Todas as Turmas'!I50) | J8: =IF('Todas as Turmas'!J50="","",'Todas as Turmas'!J50) | ... AF8: =IF('Todas as Turmas'!AF50="","",'Todas as Turmas'!AF50) | AG8: ='Todas as Turmas'!AG50 | AH8: ='Todas as Turmas'!AH50 | AI8: ='Todas as Turmas'!AI50 | AJ8: ='Todas as Turmas'!AJ50 | AK8: ='Todas as Turmas'!AK50 | AL8: ='Todas as Turmas'!AL50
A9: ='Todas as Turmas'!A51 | B9: ='Todas as Turmas'!B51 | C9: =IF('Todas as Turmas'!C51="","",'Todas as Turmas'!C51) | D9: =IF('Todas as Turmas'!D51="","",'Todas as Turmas'!D51) | E9: =IF('Todas as Turmas'!E51="","",'Todas as Turmas'!E51) | F9: =IF('Todas as Turmas'!F51="","",'Todas as Turmas'!F51) | G9: =IF('Todas as Turmas'!G51="","",'Todas as Turmas'!G51) | H9: =IF('Todas as Turmas'!H51="","",'Todas as Turmas'!H51) | I9: =IF('Todas as Turmas'!I51="","",'Todas as Turmas'!I51) | J9: =IF('Todas as Turmas'!J51="","",'Todas as Turmas'!J51) | ... AF9: =IF('Todas as Turmas'!AF51="","",'Todas as Turmas'!AF51) | AG9: ='Todas as Turmas'!AG51 | AH9: ='Todas as Turmas'!AH51 | AI9: ='Todas as Turmas'!AI51 | AJ9: ='Todas as Turmas'!AJ51 | AK9: ='Todas as Turmas'!AK51 | AL9: ='Todas as Turmas'!AL51
A10: ='Todas as Turmas'!A52 | B10: ='Todas as Turmas'!B52 | C10: =IF('Todas as Turmas'!C52="","",'Todas as Turmas'!C52) | D10: =IF('Todas as Turmas'!D52="","",'Todas as Turmas'!D52) | E10: =IF('Todas as Turmas'!E52="","",'Todas as Turmas'!E52) | F10: =IF('Todas as Turmas'!F52="","",'Todas as Turmas'!F52) | G10: =IF('Todas as Turmas'!G52="","",'Todas as Turmas'!G52) | H10: =IF('Todas as Turmas'!H52="","",'Todas as Turmas'!H52) | I10: =IF('Todas as Turmas'!I52="","",'Todas as Turmas'!I52) | J10: =IF('Todas as Turmas'!J52="","",'Todas as Turmas'!J52) | ... AF10: =IF('Todas as Turmas'!AF52="","",'Todas as Turmas'!AF52) | AG10: ='Todas as Turmas'!AG52 | AH10: ='Todas as Turmas'!AH52 | AI10: ='Todas as Turmas'!AI52 | AJ10: ='Todas as Turmas'!AJ52 | AK10: ='Todas as Turmas'!AK52 | AL10: ='Todas as Turmas'!AL52
A11: ='Todas as Turmas'!A53 | B11: ='Todas as Turmas'!B53 | C11: =IF('Todas as Turmas'!C53="","",'Todas as Turmas'!C53) | D11: =IF('Todas as Turmas'!D53="","",'Todas as Turmas'!D53) | E11: =IF('Todas as Turmas'!E53="","",'Todas as Turmas'!E53) | F11: =IF('Todas as Turmas'!F53="","",'Todas as Turmas'!F53) | G11: =IF('Todas as Turmas'!G53="","",'Todas as Turmas'!G53) | H11: =IF('Todas as Turmas'!H53="","",'Todas as Turmas'!H53) | I11: =IF('Todas as Turmas'!I53="","",'Todas as Turmas'!I53) | J11: =IF('Todas as Turmas'!J53="","",'Todas as Turmas'!J53) | ... AF11: =IF('Todas as Turmas'!AF53="","",'Todas as Turmas'!AF53) | AG11: ='Todas as Turmas'!AG53 | AH11: ='Todas as Turmas'!AH53 | AI11: ='Todas as Turmas'!AI53 | AJ11: ='Todas as Turmas'!AJ53 | AK11: ='Todas as Turmas'!AK53 | AL11: ='Todas as Turmas'!AL53

Sheet 9º ANO
A1: OBLI 2024.2 (SELETA EDUCAÇÃO) • COOEDUCAR CARLOS CHAGAS — 9º ANO
A2: Q01 a Q20: READING (Compreensão Leitora - 20 pts) | Q21 a Q30: LISTENING (Compreensão Auditiva - 10 pts)
A3: Nº | B3: Nome do Aluno | C3: Q01 | D3: Q02 | E3: Q03 | F3: Q04 | G3: Q05 | H3: Q06 | I3: Q07 | J3: Q08 | K3: Q09 | L3: Q10 | M3: Q11 | N3: Q12 | O3: Q13 | P3: Q14 | Q3: Q15 | R3: Q16 | S3: Q17 | T3: Q18 | U3: Q19 | V3: Q20 | W3: Q21 | X3: Q22 | Y3: Q23 | Z3: Q24 | AA3: Q25 | AB3: Q26 | AC3: Q27 | AD3: Q28 | AE3: Q29 | AF3: Q30 | AG3: Total (30) | AH3: % Geral | AI3: Reading (20) | AJ3: % Reading | AK3: Listening (10) | AL3: % Listening
A4: ★ | B4: [ GABARITO OFICIAL — 9º ANO ] | C4: =IF('Todas as Turmas'!C57="","",'Todas as Turmas'!C57) | D4: =IF('Todas as Turmas'!D57="","",'Todas as Turmas'!D57) | E4: =IF('Todas as Turmas'!E57="","",'Todas as Turmas'!E57) | F4: =IF('Todas as Turmas'!F57="","",'Todas as Turmas'!F57) | G4: =IF('Todas as Turmas'!G57="","",'Todas as Turmas'!G57) | H4: =IF('Todas as Turmas'!H57="","",'Todas as Turmas'!H57) | I4: =IF('Todas as Turmas'!I57="","",'Todas as Turmas'!I57) | J4: =IF('Todas as Turmas'!J57="","",'Todas as Turmas'!J57) | ... AF4: =IF('Todas as Turmas'!AF57="","",'Todas as Turmas'!AF57) | AG4: ='Todas as Turmas'!AG57 | AH4: Gabarito | AI4: ='Todas as Turmas'!AI57 | AJ4: Reading | AK4: ='Todas as Turmas'!AK57 | AL4: Listening
A5: ='Todas as Turmas'!A58 | B5: ='Todas as Turmas'!B58 | C5: =IF('Todas as Turmas'!C58="","",'Todas as Turmas'!C58) | D5: =IF('Todas as Turmas'!D58="","",'Todas as Turmas'!D58) | E5: =IF('Todas as Turmas'!E58="","",'Todas as Turmas'!E58) | F5: =IF('Todas as Turmas'!F58="","",'Todas as Turmas'!F58) | G5: =IF('Todas as Turmas'!G58="","",'Todas as Turmas'!G58) | H5: =IF('Todas as Turmas'!H58="","",'Todas as Turmas'!H58) | I5: =IF('Todas as Turmas'!I58="","",'Todas as Turmas'!I58) | J5: =IF('Todas as Turmas'!J58="","",'Todas as Turmas'!J58) | ... AF5: =IF('Todas as Turmas'!AF58="","",'Todas as Turmas'!AF58) | AG5: ='Todas as Turmas'!AG58 | AH5: ='Todas as Turmas'!AH58 | AI5: ='Todas as Turmas'!AI58 | AJ5: ='Todas as Turmas'!AJ58 | AK5: ='Todas as Turmas'!AK58 | AL5: ='Todas as Turmas'!AL58
A6: ='Todas as Turmas'!A59 | B6: ='Todas as Turmas'!B59 | C6: =IF('Todas as Turmas'!C59="","",'Todas as Turmas'!C59) | D6: =IF('Todas as Turmas'!D59="","",'Todas as Turmas'!D59) | E6: =IF('Todas as Turmas'!E59="","",'Todas as Turmas'!E59) | F6: =IF('Todas as Turmas'!F59="","",'Todas as Turmas'!F59) | G6: =IF('Todas as Turmas'!G59="","",'Todas as Turmas'!G59) | H6: =IF('Todas as Turmas'!H59="","",'Todas as Turmas'!H59) | I6: =IF('Todas as Turmas'!I59="","",'Todas as Turmas'!I59) | J6: =IF('Todas as Turmas'!J59="","",'Todas as Turmas'!J59) | ... AF6: =IF('Todas as Turmas'!AF59="","",'Todas as Turmas'!AF59) | AG6: ='Todas as Turmas'!AG59 | AH6: ='Todas as Turmas'!AH59 | AI6: ='Todas as Turmas'!AI59 | AJ6: ='Todas as Turmas'!AJ59 | AK6: ='Todas as Turmas'!AK59 | AL6: ='Todas as Turmas'!AL59
A7: ='Todas as Turmas'!A60 | B7: ='Todas as Turmas'!B60 | C7: =IF('Todas as Turmas'!C60="","",'Todas as Turmas'!C60) | D7: =IF('Todas as Turmas'!D60="","",'Todas as Turmas'!D60) | E7: =IF('Todas as Turmas'!E60="","",'Todas as Turmas'!E60) | F7: =IF('Todas as Turmas'!F60="","",'Todas as Turmas'!F60) | G7: =IF('Todas as Turmas'!G60="","",'Todas as Turmas'!G60) | H7: =IF('Todas as Turmas'!H60="","",'Todas as Turmas'!H60) | I7: =IF('Todas as Turmas'!I60="","",'Todas as Turmas'!I60) | J7: =IF('Todas as Turmas'!J60="","",'Todas as Turmas'!J60) | ... AF7: =IF('Todas as Turmas'!AF60="","",'Todas as Turmas'!AF60) | AG7: ='Todas as Turmas'!AG60 | AH7: ='Todas as Turmas'!AH60 | AI7: ='Todas as Turmas'!AI60 | AJ7: ='Todas as Turmas'!AJ60 | AK7: ='Todas as Turmas'!AK60 | AL7: ='Todas as Turmas'!AL60
A8: ='Todas as Turmas'!A61 | B8: ='Todas as Turmas'!B61 | C8: =IF('Todas as Turmas'!C61="","",'Todas as Turmas'!C61) | D8: =IF('Todas as Turmas'!D61="","",'Todas as Turmas'!D61) | E8: =IF('Todas as Turmas'!E61="","",'Todas as Turmas'!E61) | F8: =IF('Todas as Turmas'!F61="","",'Todas as Turmas'!F61) | G8: =IF('Todas as Turmas'!G61="","",'Todas as Turmas'!G61) | H8: =IF('Todas as Turmas'!H61="","",'Todas as Turmas'!H61) | I8: =IF('Todas as Turmas'!I61="","",'Todas as Turmas'!I61) | J8: =IF('Todas as Turmas'!J61="","",'Todas as Turmas'!J61) | ... AF8: =IF('Todas as Turmas'!AF61="","",'Todas as Turmas'!AF61) | AG8: ='Todas as Turmas'!AG61 | AH8: ='Todas as Turmas'!AH61 | AI8: ='Todas as Turmas'!AI61 | AJ8: ='Todas as Turmas'!AJ61 | AK8: ='Todas as Turmas'!AK61 | AL8: ='Todas as Turmas'!AL61
